Workbook

Sheet Pay Rate
A3: Depatment | B3: Hourly rate (Rupees) | C3: Overtime rate
A4: Management | B4: 350 | C4: =B4*2 -> 700
A5: HR | B5: 300 | C5: =B5*2 -> 600
A6: Finance | B6: 400 | C6: =B6*2 -> 800
A7: IT | B7: 370 | C7: =B7*2 -> 740
A8: Sales | B8: 270 | C8: =B8*2 -> 540
A9: Operations | B9: 320 | C9: =B9*2 -> 640

Sheet Attandance Tracker
A2: EMPID | B2: Name | C2: Department | D2: 1 | E2: 2 | F2: 3 | G2: 4 | H2: 5 | I2: 6 | J2: 7 | K2: 8 | L2: 9 | M2: 10 | N2: 11 | O2: 12 | P2: 13 | Q2: 14 | R2: 15 | S2: 16 | T2: 17 | U2: 18 | V2: 19 | W2: 20 | X2: 21 | Y2: 22 | Z2: 23 | AA2: 24 | AB2: 25 | AC2: 26 | AD2: 27 | AE2: 28 | AF2: 29 | AG2: 30 | AH2: 31 | AI2: Present | AJ2: Leave | AK2: Absent
A3: 1001 | B3: Amit | C3: Management | D3: P | E3: P | F3: P | G3: P | H3: P | I3: P | J3: P | K3: P | L3: P | M3: P | N3: P | O3: P | P3: P | Q3: P | R3: P | S3: P | T3: P | U3: L | V3: A | W3: P | X3: P | Y3: P | Z3: P | AA3: A | AB3: A | AC3: L | AD3: P | AE3: P | AF3: P | AG3: L | AH3: L | AI3: =COUNTIF(D3:AH3,"P") -> 24 | AJ3: =COUNTIF(D3:AH3,"L") -> 4 | AK3: =COUNTIF(D3:AH3,"A") -> 3
A4: 1002 | B4: Ravi | C4: Management | D4: P | E4: P | F4: P | G4: L | H4: L | I4: P | J4: P | K4: P | L4: A | M4: P | N4: P | O4: P | P4: P | Q4: P | R4: P | S4: P | T4: P | U4: P | V4: P | W4: P | X4: P | Y4: P | Z4: P | AA4: P | AB4: P | AC4: P | AD4: P | AE4: P | AF4: P | AG4: P | AH4: P | AI4: =COUNTIF(D4:AH4,"P") -> 28 | AJ4: =COUNTIF(D4:AH4,"L") -> 2 | AK4: =COUNTIF(D4:AH4,"A") -> 1
A5: 1003 | B5: Neha | C5: HR | D5: P | E5: P | F5: P | G5: P | H5: P | I5: P | J5: P | K5: P | L5: P | M5: P | N5: P | O5: P | P5: P | Q5: P | R5: P | S5: P | T5: P | U5: P | V5: P | W5: P | X5: P | Y5: P | Z5: P | AA5: P | AB5: P | AC5: P | AD5: P | AE5: P | AF5: P | AG5: P | AH5: P | AI5: =COUNTIF(D5:AH5,"P") -> 31 | AJ5: =COUNTIF(D5:AH5,"L") -> 0 | AK5: =COUNTIF(D5:AH5,"A") -> 0
A6: 1004 | B6: Priya | C6: Finance | D6: P | E6: P | F6: P | G6: P | H6: P | I6: P | J6: P | K6: P | L6: P | M6: P | N6: P | O6: P | P6: P | Q6: P | R6: P | S6: P | T6: P | U6: P | V6: P | W6: P | X6: P | Y6: P | Z6: P | AA6: P | AB6: P | AC6: A | AD6: A | AE6: P | AF6: P | AG6: P | AH6: P | AI6: =COUNTIF(D6:AH6,"P") -> 29 | AJ6: =COUNTIF(D6:AH6,"L") -> 0 | AK6: =COUNTIF(D6:AH6,"A") -> 2
A7: 1005 | B7: Rohit | C7: IT | D7: P | E7: P | F7: P | G7: P | H7: P | I7: P | J7: P | K7: P | L7: P | M7: P | N7: P | O7: P | P7: P | Q7: P | R7: P | S7: P | T7: P | U7: P | V7: P | W7: P | X7: P | Y7: P | Z7: P | AA7: P | AB7: P | AC7: P | AD7: P | AE7: P | AF7: P | AG7: P | AH7: L | AI7: =COUNTIF(D7:AH7,"P") -> 30 | AJ7: =COUNTIF(D7:AH7,"L") -> 1 | AK7: =COUNTIF(D7:AH7,"A") -> 0
A8: 1006 | B8: Anjali | C8: Sales | D8: P | E8: P | F8: P | G8: P | H8: P | I8: P | J8: P | K8: P | L8: P | M8: P | N8: P | O8: P | P8: P | Q8: P | R8: P | S8: P | T8: P | U8: P | V8: P | W8: P | X8: P | Y8: P | Z8: P | AA8: P | AB8: P | AC8: P | AD8: P | AE8: P | AF8: P | AG8: P | AH8: P | AI8: =COUNTIF(D8:AH8,"P") -> 31 | AJ8: =COUNTIF(D8:AH8,"L") -> 0 | AK8: =COUNTIF(D8:AH8,"A") -> 0
A9: 1007 | B9: Vikas | C9: Operations | D9: L | E9: L | F9: L | G9: L | H9: P | I9: P | J9: P | K9: P | L9: P | M9: P | N9: P | O9: P | P9: P | Q9: P | R9: P | S9: P | T9: P | U9: P | V9: P | W9: P | X9: P | Y9: P | Z9: P | AA9: P | AB9: P | AC9: P | AD9: P | AE9: P | AF9: P | AG9: P | AH9: P | AI9: =COUNTIF(D9:AH9,"P") -> 27 | AJ9: =COUNTIF(D9:AH9,"L") -> 4 | AK9: =COUNTIF(D9:AH9,"A") -> 0
A10: 1008 | B10: Pooja | C10: HR | D10: P | E10: P | F10: P | G10: P | H10: P | I10: P | J10: P | K10: P | L10: P | M10: P | N10: P | O10: P | P10: P | Q10: P | R10: P | S10: P | T10: P | U10: P | V10: P | W10: P | X10: P | Y10: P | Z10: P | AA10: P | AB10: P | AC10: P | AD10: P | AE10: P | AF10: P | AG10: P | AH10: P | AI10: =COUNTIF(D10:AH10,"P") -> 31 | AJ10: =COUNTIF(D10:AH10,"L") -> 0 | AK10: =COUNTIF(D10:AH10,"A") -> 0
A11: 1009 | B11: Arjun | C11: HR | D11: P | E11: P | F11: P | G11: P | H11: P | I11: P | J11: P | K11: P | L11: P | M11: P | N11: P | O11: P | P11: P | Q11: P | R11: P | S11: P | T11: P | U11: L | V11: A | W11: P | X11: P | Y11: P | Z11: P | AA11: A | AB11: A | AC11: L | AD11: P | AE11: P | AF11: P | AG11: L | AH11: L | AI11: =COUNTIF(D11:AH11,"P") -> 24 | AJ11: =COUNTIF(D11:AH11,"L") -> 4 | AK11: =COUNTIF(D11:AH11,"A") -> 3
A12: 1010 | B12: Sneha | C12: Finance | D12: P | E12: P | F12: P | G12: L | H12: L | I12: P | J12: P | K12: P | L12: A | M12: P | N12: P | O12: P | P12: P | Q12: P | R12: P | S12: P | T12: P | U12: P | V12: P | W12: P | X12: P | Y12: P | Z12: P | AA12: P | AB12: P | AC12: P | AD12: P | AE12: P | AF12: P | AG12: P | AH12: P | AI12: =COUNTIF(D12:AH12,"P") -> 28 | AJ12: =COUNTIF(D12:AH12,"L") -> 2 | AK12: =COUNTIF(D12:AH12,"A") -> 1
A13: 1011 | B13: Karan | C13: Finance | D13: P | E13: P | F13: P | G13: P | H13: P | I13: P | J13: P | K13: P | L13: P | M13: P | N13: P | O13: P | P13: P | Q13: P | R13: P | S13: P | T13: P | U13: P | V13: P | W13: P | X13: P | Y13: P | Z13: P | AA13: P | AB13: P | AC13: P | AD13: P | AE13: P | AF13: P | AG13: P | AH13: P | AI13: =COUNTIF(D13:AH13,"P") -> 31 | AJ13: =COUNTIF(D13:AH13,"L") -> 0 | AK13: =COUNTIF(D13:AH13,"A") -> 0
A14: 1012 | B14: Simran | C14: IT | D14: P | E14: P | F14: P | G14: P | H14: P | I14: P | J14: P | K14: P | L14: P | M14: P | N14: P | O14: P | P14: P | Q14: P | R14: P | S14: P | T14: P | U14: P | V14: P | W14: P | X14: P | Y14: P | Z14: P | AA14: P | AB14: P | AC14: A | AD14: A | AE14: P | AF14: P | AG14: P | AH14: P | AI14: =COUNTIF(D14:AH14,"P") -> 29 | AJ14: =COUNTIF(D14:AH14,"L") -> 0 | AK14: =COUNTIF(D14:AH14,"A") -> 2
... A30: 1028 | B30: Preeti | C30: IT | D30: P | E30: P | F30: P | G30: P | H30: P | I30: P | J30: P | K30: P | L30: P | M30: P | N30: P | O30: P | P30: P | Q30: P | R30: P | S30: P | T30: P | U30: P | V30: P | W30: P | X30: P | Y30: P | Z30: P | AA30: P | AB30: P | AC30: A | AD30: A | AE30: P | AF30: P | AG30: P | AH30: P | AI30: =COUNTIF(D30:AH30,"P") -> 29 | AJ30: =COUNTIF(D30:AH30,"L") -> 0 | AK30: =COUNTIF(D30:AH30,"A") -> 2

Sheet Daily Entry
L1: 1027
A3: Emp ID | B3: Employee Name | C3: Department | D3: Day (1-31) | E3: Check-In (HH:MM) | F3: Check-Out (HH:MM) | G3: Hours Worked | H3: OT HOURS | I3: Status | K3: Emp ID | L3: Employee Name | M3: Department | N3: Day (1-31) | O3: Check-In (HH:MM) | P3: Check-Out (HH:MM) | Q3: Hours Worked | R3: OT HOURS | S3: Status
A4: 1001 | B4: =_xlfn.IFNA(INDEX('Attandance Tracker'!$B$3:$B$30,MATCH($A4,'Attandance Tracker'!$A$3:$A$30,0)),"") -> Amit | C4: =_xlfn.IFNA(INDEX('Attandance Tracker'!$C$3:$C$30,MATCH($A4,'Attandance Tracker'!$A$3:$A$30,0)),"") -> Management | D4: 1 | E4: 0.33333333 | F4: 0.75 | G4: =IF(I4="Present",MIN(F4-E4,8/24),IF(I4="Absent",8/24,0)) -> 0.33333333 | H4: =IF(I4="Present",MAX(0,F4-E4-8/24),0) -> 0.083333333 | I4: =IFERROR(IF(INDEX('Attandance Tracker'!$D$3:$AH$50,MATCH($A4,'Attandance Tracker'!$A$3:$A$50,0),DAY($D4))="P","Present",IF(INDEX('Attandance Tracker'!$D$3:$AH$50,MATCH($A4,'Attandance Tracker'!$A$3:$A$50,0),DAY($D4))="A","Absent","Leave")),"") -> Present
A5: 1001 | B5: =_xlfn.IFNA(INDEX('Attandance Tracker'!$B$3:$B$30,MATCH($A5,'Attandance Tracker'!$A$3:$A$30,0)),"") -> Amit | C5: =_xlfn.IFNA(INDEX('Attandance Tracker'!$C$3:$C$30,MATCH($A5,'Attandance Tracker'!$A$3:$A$30,0)),"") -> Management | D5: 2 | E5: 0.375 | F5: 0.75 | G5: =IF(I5="Present",MIN(F5-E5,8/24),IF(I5="Absent",8/24,0)) -> 0.33333333 | H5: =IF(I5="Present",MAX(0,F5-E5-8/24),0) -> 0.041666667 | I5: =IFERROR(IF(INDEX('Attandance Tracker'!$D$3:$AH$50,MATCH($A5,'Attandance Tracker'!$A$3:$A$50,0),DAY($D5))="P","Present",IF(INDEX('Attandance Tracker'!$D$3:$AH$50,MATCH($A5,'Attandance Tracker'!$A$3:$A$50,0),DAY($D5))="A","Absent","Leave")),"") -> Present
A6: 1001 | B6: =_xlfn.IFNA(INDEX('Attandance Tracker'!$B$3:$B$30,MATCH($A6,'Attandance Tracker'!$A$3:$A$30,0)),"") -> Amit | C6: =_xlfn.IFNA(INDEX('Attandance Tracker'!$C$3:$C$30,MATCH($A6,'Attandance Tracker'!$A$3:$A$30,0)),"") -> Management | D6: 3 | E6: 0.375 | F6: 0.83333333 | G6: =IF(I6="Present",MIN(F6-E6,8/24),IF(I6="Absent",8/24,0)) -> 0.33333333 | H6: =IF(I6="Present",MAX(0,F6-E6-8/24),0) -> 0.125 | I6: =IFERROR(IF(INDEX('Attandance Tracker'!$D$3:$AH$50,MATCH($A6,'Attandance Tracker'!$A$3:$A$50,0),DAY($D6))="P","Present",IF(INDEX('Attandance Tracker'!$D$3:$AH$50,MATCH($A6,'Attandance Tracker'!$A$3:$A$50,0),DAY($D6))="A","Absent","Leave")),"") -> Present | O6: =IFERROR(INDEX($E$4:$E$1000,SMALL(IF($A$4:$A$1000=$O$2,ROW($A$4:$A$1000)-3),ROW(A3))),"") | P6: =IFERROR(INDEX($F$4:$F$1000,SMALL(IF($A$4:$A$1000=$O$2,ROW($A$4:$A$1000)-3),ROW(A3))),"") | Q6: =IFERROR(INDEX($G$4:$G$1000,SMALL(IF($A$4:$A$1000=$O$2,ROW($A$4:$A$1000)-3),ROW(A3))),"") | R6: =IFERROR(INDEX($H$4:$H$1000,SMALL(IF($A$4:$A$1000=$O$2,ROW($A$4:$A$1000)-3),ROW(A3))),"") | S6: =IFERROR(INDEX($I$4:$I$1000,SMALL(IF($A$4:$A$1000=$O$2,ROW($A$4:$A$1000)-3),ROW(A3))),"")
A7: 1001 | B7: =_xlfn.IFNA(INDEX('Attandance Tracker'!$B$3:$B$30,MATCH($A7,'Attandance Tracker'!$A$3:$A$30,0)),"") -> Amit | C7: =_xlfn.IFNA(INDEX('Attandance Tracker'!$C$3:$C$30,MATCH($A7,'Attandance Tracker'!$A$3:$A$30,0)),"") -> Management | D7: 4 | E7: 0.375 | F7: 0.83333333 | G7: =IF(I7="Present",MIN(F7-E7,8/24),IF(I7="Absent",8/24,0)) -> 0.33333333 | H7: =IF(I7="Present",MAX(0,F7-E7-8/24),0) -> 0.125 | I7: =IFERROR(IF(INDEX('Attandance Tracker'!$D$3:$AH$50,MATCH($A7,'Attandance Tracker'!$A$3:$A$50,0),DAY($D7))="P","Present",IF(INDEX('Attandance Tracker'!$D$3:$AH$50,MATCH($A7,'Attandance Tracker'!$A$3:$A$50,0),DAY($D7))="A","Absent","Leave")),"") -> Present | O7: =IFERROR(INDEX($E$4:$E$1000,SMALL(IF($A$4:$A$1000=$O$2,ROW($A$4:$A$1000)-3),ROW(A4))),"") | P7: =IFERROR(INDEX($F$4:$F$1000,SMALL(IF($A$4:$A$1000=$O$2,ROW($A$4:$A$1000)-3),ROW(A4))),"") | Q7: =IFERROR(INDEX($G$4:$G$1000,SMALL(IF($A$4:$A$1000=$O$2,ROW($A$4:$A$1000)-3),ROW(A4))),"") | R7: =IFERROR(INDEX($H$4:$H$1000,SMALL(IF($A$4:$A$1000=$O$2,ROW($A$4:$A$1000)-3),ROW(A4))),"") | S7: =IFERROR(INDEX($I$4:$I$1000,SMALL(IF($A$4:$A$1000=$O$2,ROW($A$4:$A$1000)-3),ROW(A4))),"")
A8: 1001 | B8: =_xlfn.IFNA(INDEX('Attandance Tracker'!$B$3:$B$30,MATCH($A8,'Attandance Tracker'!$A$3:$A$30,0)),"") -> Amit | C8: =_xlfn.IFNA(INDEX('Attandance Tracker'!$C$3:$C$30,MATCH($A8,'Attandance Tracker'!$A$3:$A$30,0)),"") -> Management | D8: 5 | E8: 0.33333333 | F8: 0.83333333 | G8: =IF(I8="Present",MIN(F8-E8,8/24),IF(I8="Absent",8/24,0)) -> 0.33333333 | H8: =IF(I8="Present",MAX(0,F8-E8-8/24),0) -> 0.16666667 | I8: =IFERROR(IF(INDEX('Attandance Tracker'!$D$3:$AH$50,MATCH($A8,'Attandance Tracker'!$A$3:$A$50,0),DAY($D8))="P","Present",IF(INDEX('Attandance Tracker'!$D$3:$AH$50,MATCH($A8,'Attandance Tracker'!$A$3:$A$50,0),DAY($D8))="A","Absent","Leave")),"") -> Present | O8: =IFERROR(INDEX($E$4:$E$1000,SMALL(IF($A$4:$A$1000=$O$2,ROW($A$4:$A$1000)-3),ROW(A5))),"") | P8: =IFERROR(INDEX($F$4:$F$1000,SMALL(IF($A$4:$A$1000=$O$2,ROW($A$4:$A$1000)-3),ROW(A5))),"") | Q8: =IFERROR(INDEX($G$4:$G$1000,SMALL(IF($A$4:$A$1000=$O$2,ROW($A$4:$A$1000)-3),ROW(A5))),"") | R8: =IFERROR(INDEX($H$4:$H$1000,SMALL(IF($A$4:$A$1000=$O$2,ROW($A$4:$A$1000)-3),ROW(A5))),"") | S8: =IFERROR(INDEX($I$4:$I$1000,SMALL(IF($A$4:$A$1000=$O$2,ROW($A$4:$A$1000)-3),ROW(A5))),"")
A9: 1001 | B9: =_xlfn.IFNA(INDEX('Attandance Tracker'!$B$3:$B$30,MATCH($A9,'Attandance Tracker'!$A$3:$A$30,0)),"") -> Amit | C9: =_xlfn.IFNA(INDEX('Attandance Tracker'!$C$3:$C$30,MATCH($A9,'Attandance Tracker'!$A$3:$A$30,0)),"") -> Management | D9: 6 | E9: 0.33333333 | F9: 0.79166667 | G9: =IF(I9="Present",MIN(F9-E9,8/24),IF(I9="Absent",8/24,0)) -> 0.33333333 | H9: =IF(I9="Present",MAX(0,F9-E9-8/24),0) -> 0.125 | I9: =IFERROR(IF(INDEX('Attandance Tracker'!$D$3:$AH$50,MATCH($A9,'Attandance Tracker'!$A$3:$A$50,0),DAY($D9))="P","Present",IF(INDEX('Attandance Tracker'!$D$3:$AH$50,MATCH($A9,'Attandance Tracker'!$A$3:$A$50,0),DAY($D9))="A","Absent","Leave")),"") -> Present | O9: =IFERROR(INDEX($E$4:$E$1000,SMALL(IF($A$4:$A$1000=$O$2,ROW($A$4:$A$1000)-3),ROW(A6))),"") | P9: =IFERROR(INDEX($F$4:$F$1000,SMALL(IF($A$4:$A$1000=$O$2,ROW($A$4:$A$1000)-3),ROW(A6))),"") | Q9: =IFERROR(INDEX($G$4:$G$1000,SMALL(IF($A$4:$A$1000=$O$2,ROW($A$4:$A$1000)-3),ROW(A6))),"") | R9: =IFERROR(INDEX($H$4:$H$1000,SMALL(IF($A$4:$A$1000=$O$2,ROW($A$4:$A$1000)-3),ROW(A6))),"") | S9: =IFERROR(INDEX($I$4:$I$1000,SMALL(IF($A$4:$A$1000=$O$2,ROW($A$4:$A$1000)-3),ROW(A6))),"")
A10: 1001 | B10: =_xlfn.IFNA(INDEX('Attandance Tracker'!$B$3:$B$30,MATCH($A10,'Attandance Tracker'!$A$3:$A$30,0)),"") -> Amit | C10: =_xlfn.IFNA(INDEX('Attandance Tracker'!$C$3:$C$30,MATCH($A10,'Attandance Tracker'!$A$3:$A$30,0)),"") -> Management | D10: 7 | E10: 0.33333333 | F10: 0.75 | G10: =IF(I10="Present",MIN(F10-E10,8/24),IF(I10="Absent",8/24,0)) -> 0.33333333 | H10: =IF(I10="Present",MAX(0,F10-E10-8/24),0) -> 0.083333333 | I10: =IFERROR(IF(INDEX('Attandance Tracker'!$D$3:$AH$50,MATCH($A10,'Attandance Tracker'!$A$3:$A$50,0),DAY($D10))="P","Present",IF(INDEX('Attandance Tracker'!$D$3:$AH$50,MATCH($A10,'Attandance Tracker'!$A$3:$A$50,0),DAY($D10))="A","Absent","Leave")),"") -> Present | O10: =IFERROR(INDEX($E$4:$E$1000,SMALL(IF($A$4:$A$1000=$O$2,ROW($A$4:$A$1000)-3),ROW(A7))),"") | P10: =IFERROR(INDEX($F$4:$F$1000,SMALL(IF($A$4:$A$1000=$O$2,ROW($A$4:$A$1000)-3),ROW(A7))),"") | Q10: =IFERROR(INDEX($G$4:$G$1000,SMALL(IF($A$4:$A$1000=$O$2,ROW($A$4:$A$1000)-3),ROW(A7))),"") | R10: =IFERROR(INDEX($H$4:$H$1000,SMALL(IF($A$4:$A$1000=$O$2,ROW($A$4:$A$1000)-3),ROW(A7))),"") | S10: =IFERROR(INDEX($I$4:$I$1000,SMALL(IF($A$4:$A$1000=$O$2,ROW($A$4:$A$1000)-3),ROW(A7))),"")
A11: 1001 | B11: =_xlfn.IFNA(INDEX('Attandance Tracker'!$B$3:$B$30,MATCH($A11,'Attandance Tracker'!$A$3:$A$30,0)),"") -> Amit | C11: =_xlfn.IFNA(INDEX('Attandance Tracker'!$C$3:$C$30,MATCH($A11,'Attandance Tracker'!$A$3:$A$30,0)),"") -> Management | D11: 8 | E11: 0.33333333 | F11: 0.75 | G11: =IF(I11="Present",MIN(F11-E11,8/24),IF(I11="Absent",8/24,0)) -> 0.33333333 | H11: =IF(I11="Present",MAX(0,F11-E11-8/24),0) -> 0.083333333 | I11: =IFERROR(IF(INDEX('Attandance Tracker'!$D$3:$AH$50,MATCH($A11,'Attandance Tracker'!$A$3:$A$50,0),DAY($D11))="P","Present",IF(INDEX('Attandance Tracker'!$D$3:$AH$50,MATCH($A11,'Attandance Tracker'!$A$3:$A$50,0),DAY($D11))="A","Absent","Leave")),"") -> Present | O11: =IFERROR(INDEX($E$4:$E$1000,SMALL(IF($A$4:$A$1000=$O$2,ROW($A$4:$A$1000)-3),ROW(A8))),"") | P11: =IFERROR(INDEX($F$4:$F$1000,SMALL(IF($A$4:$A$1000=$O$2,ROW($A$4:$A$1000)-3),ROW(A8))),"") | Q11: =IFERROR(INDEX($G$4:$G$1000,SMALL(IF($A$4:$A$1000=$O$2,ROW($A$4:$A$1000)-3),ROW(A8))),"") | R11: =IFERROR(INDEX($H$4:$H$1000,SMALL(IF($A$4:$A$1000=$O$2,ROW($A$4:$A$1000)-3),ROW(A8))),"") | S11: =IFERROR(INDEX($I$4:$I$1000,SMALL(IF($A$4:$A$1000=$O$2,ROW($A$4:$A$1000)-3),ROW(A8))),"")
A12: 1001 | B12: =_xlfn.IFNA(INDEX('Attandance Tracker'!$B$3:$B$30,MATCH($A12,'Attandance Tracker'!$A$3:$A$30,0)),"") -> Amit | C12: =_xlfn.IFNA(INDEX('Attandance Tracker'!$C$3:$C$30,MATCH($A12,'Attandance Tracker'!$A$3:$A$30,0)),"") -> Management | D12: 9 | E12: 0.33333333 | F12: 0.75 | G12: =IF(I12="Present",MIN(F12-E12,8/24),IF(I12="Absent",8/24,0)) -> 0.33333333 | H12: =IF(I12="Present",MAX(0,F12-E12-8/24),0) -> 0.083333333 | I12: =IFERROR(IF(INDEX('Attandance Tracker'!$D$3:$AH$50,MATCH($A12,'Attandance Tracker'!$A$3:$A$50,0),DAY($D12))="P","Present",IF(INDEX('Attandance Tracker'!$D$3:$AH$50,MATCH($A12,'Attandance Tracker'!$A$3:$A$50,0),DAY($D12))="A","Absent","Leave")),"") -> Present | O12: =IFERROR(INDEX($E$4:$E$1000,SMALL(IF($A$4:$A$1000=$O$2,ROW($A$4:$A$1000)-3),ROW(A9))),"") | P12: =IFERROR(INDEX($F$4:$F$1000,SMALL(IF($A$4:$A$1000=$O$2,ROW($A$4:$A$1000)-3),ROW(A9))),"") | Q12: =IFERROR(INDEX($G$4:$G$1000,SMALL(IF($A$4:$A$1000=$O$2,ROW($A$4:$A$1000)-3),ROW(A9))),"") | R12: =IFERROR(INDEX($H$4:$H$1000,SMALL(IF($A$4:$A$1000=$O$2,ROW($A$4:$A$1000)-3),ROW(A9))),"") | S12: =IFERROR(INDEX($I$4:$I$1000,SMALL(IF($A$4:$A$1000=$O$2,ROW($A$4:$A$1000)-3),ROW(A9))),"")
A13: 1001 | B13: =_xlfn.IFNA(INDEX('Attandance Tracker'!$B$3:$B$30,MATCH($A13,'Attandance Tracker'!$A$3:$A$30,0)),"") -> Amit | C13: =_xlfn.IFNA(INDEX('Attandance Tracker'!$C$3:$C$30,MATCH($A13,'Attandance Tracker'!$A$3:$A$30,0)),"") -> Management | D13: 10 | E13: 0.33333333 | F13: 0.75 | G13: =IF(I13="Present",MIN(F13-E13,8/24),IF(I13="Absent",8/24,0)) -> 0.33333333 | H13: =IF(I13="Present",MAX(0,F13-E13-8/24),0) -> 0.083333333 | I13: =IFERROR(IF(INDEX('Attandance Tracker'!$D$3:$AH$50,MATCH($A13,'Attandance Tracker'!$A$3:$A$50,0),DAY($D13))="P","Present",IF(INDEX('Attandance Tracker'!$D$3:$AH$50,MATCH($A13,'Attandance Tracker'!$A$3:$A$50,0),DAY($D13))="A","Absent","Leave")),"") -> Present | O13: =IFERROR(INDEX($E$4:$E$1000,SMALL(IF($A$4:$A$1000=$O$2,ROW($A$4:$A$1000)-3),ROW(A10))),"") | P13: =IFERROR(INDEX($F$4:$F$1000,SMALL(IF($A$4:$A$1000=$O$2,ROW($A$4:$A$1000)-3),ROW(A10))),"") | Q13: =IFERROR(INDEX($G$4:$G$1000,SMALL(IF($A$4:$A$1000=$O$2,ROW($A$4:$A$1000)-3),ROW(A10))),"") | R13: =IFERROR(INDEX($H$4:$H$1000,SMALL(IF($A$4:$A$1000=$O$2,ROW($A$4:$A$1000)-3),ROW(A10))),"") | S13: =IFERROR(INDEX($I$4:$I$1000,SMALL(IF($A$4:$A$1000=$O$2,ROW($A$4:$A$1000)-3),ROW(A10))),"")
A14: 1001 | B14: =_xlfn.IFNA(INDEX('Attandance Tracker'!$B$3:$B$30,MATCH($A14,'Attandance Tracker'!$A$3:$A$30,0)),"") -> Amit | C14: =_xlfn.IFNA(INDEX('Attandance Tracker'!$C$3:$C$30,MATCH($A14,'Attandance Tracker'!$A$3:$A$30,0)),"") -> Management | D14: 11 | E14: 0.33333333 | F14: 0.75 | G14: =IF(I14="Present",MIN(F14-E14,8/24),IF(I14="Absent",8/24,0)) -> 0.33333333 | H14: =IF(I14="Present",MAX(0,F14-E14-8/24),0) -> 0.083333333 | I14: =IFERROR(IF(INDEX('Attandance Tracker'!$D$3:$AH$50,MATCH($A14,'Attandance Tracker'!$A$3:$A$50,0),DAY($D14))="P","Present",IF(INDEX('Attandance Tracker'!$D$3:$AH$50,MATCH($A14,'Attandance Tracker'!$A$3:$A$50,0),DAY($D14))="A","Absent","Leave")),"") -> Present | O14: =IFERROR(INDEX($E$4:$E$1000,SMALL(IF($A$4:$A$1000=$O$2,ROW($A$4:$A$1000)-3),ROW(A11))),"") | P14: =IFERROR(INDEX($F$4:$F$1000,SMALL(IF($A$4:$A$1000=$O$2,ROW($A$4:$A$1000)-3),ROW(A11))),"") | Q14: =IFERROR(INDEX($G$4:$G$1000,SMALL(IF($A$4:$A$1000=$O$2,ROW($A$4:$A$1000)-3),ROW(A11))),"") | R14: =IFERROR(INDEX($H$4:$H$1000,SMALL(IF($A$4:$A$1000=$O$2,ROW($A$4:$A$1000)-3),ROW(A11))),"") | S14: =IFERROR(INDEX($I$4:$I$1000,SMALL(IF($A$4:$A$1000=$O$2,ROW($A$4:$A$1000)-3),ROW(A11))),"")
A15: 1001 | B15: =_xlfn.IFNA(INDEX('Attandance Tracker'!$B$3:$B$30,MATCH($A15,'Attandance Tracker'!$A$3:$A$30,0)),"") -> Amit | C15: =_xlfn.IFNA(INDEX('Attandance Tracker'!$C$3:$C$30,MATCH($A15,'Attandance Tracker'!$A$3:$A$30,0)),"") -> Management | D15: 12 | E15: 0.375 | F15: 0.75 | G15: =IF(I15="Present",MIN(F15-E15,8/24),IF(I15="Absent",8/24,0)) -> 0.33333333 | H15: =IF(I15="Present",MAX(0,F15-E15-8/24),0) -> 0.041666667 | I15: =IFERROR(IF(INDEX('Attandance Tracker'!$D$3:$AH$50,MATCH($A15,'Attandance Tracker'!$A$3:$A$50,0),DAY($D15))="P","Present",IF(INDEX('Attandance Tracker'!$D$3:$AH$50,MATCH($A15,'Attandance Tracker'!$A$3:$A$50,0),DAY($D15))="A","Absent","Leave")),"") -> Present | O15: =IFERROR(INDEX($E$4:$E$1000,SMALL(IF($A$4:$A$1000=$O$2,ROW($A$4:$A$1000)-3),ROW(A12))),"") | P15: =IFERROR(INDEX($F$4:$F$1000,SMALL(IF($A$4:$A$1000=$O$2,ROW($A$4:$A$1000)-3),ROW(A12))),"") | Q15: =IFERROR(INDEX($G$4:$G$1000,SMALL(IF($A$4:$A$1000=$O$2,ROW($A$4:$A$1000)-3),ROW(A12))),"") | R15: =IFERROR(INDEX($H$4:$H$1000,SMALL(IF($A$4:$A$1000=$O$2,ROW($A$4:$A$1000)-3),ROW(A12))),"") | S15: =IFERROR(INDEX($I$4:$I$1000,SMALL(IF($A$4:$A$1000=$O$2,ROW($A$4:$A$1000)-3),ROW(A12))),"")
A16: 1001 | B16: =_xlfn.IFNA(INDEX('Attandance Tracker'!$B$3:$B$30,MATCH($A16,'Attandance Tracker'!$A$3:$A$30,0)),"") -> Amit | C16: =_xlfn.IFNA(INDEX('Attandance Tracker'!$C$3:$C$30,MATCH($A16,'Attandance Tracker'!$A$3:$A$30,0)),"") -> Management | D16: 13 | E16: 0.375 | F16: 0.83333333 | G16: =IF(I16="Present",MIN(F16-E16,8/24),IF(I16="Absent",8/24,0)) -> 0.33333333 | H16: =IF(I16="Present",MAX(0,F16-E16-8/24),0) -> 0.125 | I16: =IFERROR(IF(INDEX('Attandance Tracker'!$D$3:$AH$50,MATCH($A16,'Attandance Tracker'!$A$3:$A$50,0),DAY($D16))="P","Present",IF(INDEX('Attandance Tracker'!$D$3:$AH$50,MATCH($A16,'Attandance Tracker'!$A$3:$A$50,0),DAY($D16))="A","Absent","Leave")),"") -> Present | O16: =IFERROR(INDEX($E$4:$E$1000,SMALL(IF($A$4:$A$1000=$O$2,ROW($A$4:$A$1000)-3),ROW(A13))),"") | P16: =IFERROR(INDEX($F$4:$F$1000,SMALL(IF($A$4:$A$1000=$O$2,ROW($A$4:$A$1000)-3),ROW(A13))),"") | Q16: =IFERROR(INDEX($G$4:$G$1000,SMALL(IF($A$4:$A$1000=$O$2,ROW($A$4:$A$1000)-3),ROW(A13))),"") | R16: =IFERROR(INDEX($H$4:$H$1000,SMALL(IF($A$4:$A$1000=$O$2,ROW($A$4:$A$1000)-3),ROW(A13))),"") | S16: =IFERROR(INDEX($I$4:$I$1000,SMALL(IF($A$4:$A$1000=$O$2,ROW($A$4:$A$1000)-3),ROW(A13))),"")
A17: 1001 | B17: =_xlfn.IFNA(INDEX('Attandance Tracker'!$B$3:$B$30,MATCH($A17,'Attandance Tracker'!$A$3:$A$30,0)),"") -> Amit | C17: =_xlfn.IFNA(INDEX('Attandance Tracker'!$C$3:$C$30,MATCH($A17,'Attandance Tracker'!$A$3:$A$30,0)),"") -> Management | D17: 14 | E17: 0.375 | F17: 0.83333333 | G17: =IF(I17="Present",MIN(F17-E17,8/24),IF(I17="Absent",8/24,0)) -> 0.33333333 | H17: =IF(I17="Present",MAX(0,F17-E17-8/24),0) -> 0.125 | I17: =IFERROR(IF(INDEX('Attandance Tracker'!$D$3:$AH$50,MATCH($A17,'Attandance Tracker'!$A$3:$A$50,0),DAY($D17))="P","Present",IF(INDEX('Attandance Tracker'!$D$3:$AH$50,MATCH($A17,'Attandance Tracker'!$A$3:$A$50,0),DAY($D17))="A","Absent","Leave")),"") -> Present | O17: =IFERROR(INDEX($E$4:$E$1000,SMALL(IF($A$4:$A$1000=$O$2,ROW($A$4:$A$1000)-3),ROW(A14))),"") | P17: =IFERROR(INDEX($F$4:$F$1000,SMALL(IF($A$4:$A$1000=$O$2,ROW($A$4:$A$1000)-3),ROW(A14))),"") | Q17: =IFERROR(INDEX($G$4:$G$1000,SMALL(IF($A$4:$A$1000=$O$2,ROW($A$4:$A$1000)-3),ROW(A14))),"") | R17: =IFERROR(INDEX($H$4:$H$1000,SMALL(IF($A$4:$A$1000=$O$2,ROW($A$4:$A$1000)-3),ROW(A14))),"") | S17: =IFERROR(INDEX($I$4:$I$1000,SMALL(IF($A$4:$A$1000=$O$2,ROW($A$4:$A$1000)-3),ROW(A14))),"")
... A22: 1001 | B22: =_xlfn.IFNA(INDEX('Attandance Tracker'!$B$3:$B$30,MATCH($A22,'Attandance Tracker'!$A$3:$A$30,0)),"") -> Amit | C22: =_xlfn.IFNA(INDEX('Attandance Tracker'!$C$3:$C$30,MATCH($A22,'Attandance Tracker'!$A$3:$A$30,0)),"") -> Management | D22: 19 | E22: 0.33333333 | F22: 0.75 | G22: =IF(I22="Present",MIN(F22-E22,8/24),IF(I22="Absent",8/24,0)) -> 0.33333333 | H22: =IF(I22="Present",MAX(0,F22-E22-8/24),0) -> 0 | I22: =IFERROR(IF(INDEX('Attandance Tracker'!$D$3:$AH$50,MATCH($A22,'Attandance Tracker'!$A$3:$A$50,0),DAY($D22))="P","Present",IF(INDEX('Attandance Tracker'!$D$3:$AH$50,MATCH($A22,'Attandance Tracker'!$A$3:$A$50,0),DAY($D22))="A","Absent","Leave")),"") -> Absent | O22: =IFERROR(INDEX($E$4:$E$1000,SMALL(IF($A$4:$A$1000=$O$2,ROW($A$4:$A$1000)-3),ROW(A19))),"") | P22: =IFERROR(INDEX($F$4:$F$1000,SMALL(IF($A$4:$A$1000=$O$2,ROW($A$4:$A$1000)-3),ROW(A19))),"") | Q22: =IFERROR(INDEX($G$4:$G$1000,SMALL(IF($A$4:$A$1000=$O$2,ROW($A$4:$A$1000)-3),ROW(A19))),"") | R22: =IFERROR(INDEX($H$4:$H$1000,SMALL(IF($A$4:$A$1000=$O$2,ROW($A$4:$A$1000)-3),ROW(A19))),"") | S22: =IFERROR(INDEX($I$4:$I$1000,SMALL(IF($A$4:$A$1000=$O$2,ROW($A$4:$A$1000)-3),ROW(A19))),"")
A23: 1001 | B23: =_xlfn.IFNA(INDEX('Attandance Tracker'!$B$3:$B$30,MATCH($A23,'Attandance Tracker'!$A$3:$A$30,0)),"") -> Amit | C23: =_xlfn.IFNA(INDEX('Attandance Tracker'!$C$3:$C$30,MATCH($A23,'Attandance Tracker'!$A$3:$A$30,0)),"") -> Management | D23: 20 | E23: 0.33333333 | F23: 0.75 | G23: =IF(I23="Present",MIN(F23-E23,8/24),IF(I23="Absent",8/24,0)) -> 0.33333333 | H23: =IF(I23="Present",MAX(0,F23-E23-8/24),0) -> 0.083333333 | I23: =IFERROR(IF(INDEX('Attandance Tracker'!$D$3:$AH$50,MATCH($A23,'Attandance Tracker'!$A$3:$A$50,0),DAY($D23))="P","Present",IF(INDEX('Attandance Tracker'!$D$3:$AH$50,MATCH($A23,'Attandance Tracker'!$A$3:$A$50,0),DAY($D23))="A","Absent","Leave")),"") -> Present | K23: =IFERROR(INDEX($A$4:$A$1000,SMALL(IF($A$4:$A$1000=$O$2,ROW($A$4:$A$1000)-3),ROW(A20))),"") | L23: =IFERROR(INDEX($B$4:$B$1000,SMALL(IF($A$4:$A$1000=$O$2,ROW($A$4:$A$1000)-3),ROW(A20))),"") | M23: =IFERROR(INDEX($C$4:$C$1000,SMALL(IF($A$4:$A$1000=$O$2,ROW($A$4:$A$1000)-3),ROW(A20))),"") | N23: =IFERROR(INDEX($D$4:$D$1000,SMALL(IF($A$4:$A$1000=$O$2,ROW($A$4:$A$1000)-3),ROW(A20))),"") | O23: =IFERROR(INDEX($E$4:$E$1000,SMALL(IF($A$4:$A$1000=$O$2,ROW($A$4:$A$1000)-3),ROW(A20))),"") | P23: =IFERROR(INDEX($F$4:$F$1000,SMALL(IF($A$4:$A$1000=$O$2,ROW($A$4:$A$1000)-3),ROW(A20))),"") | Q23: =IFERROR(INDEX($G$4:$G$1000,SMALL(IF($A$4:$A$1000=$O$2,ROW($A$4:$A$1000)-3),ROW(A20))),"") | R23: =IFERROR(INDEX($H$4:$H$1000,SMALL(IF($A$4:$A$1000=$O$2,ROW($A$4:$A$1000)-3),ROW(A20))),"") | S23: =IFERROR(INDEX($I$4:$I$1000,SMALL(IF($A$4:$A$1000=$O$2,ROW($A$4:$A$1000)-3),ROW(A20))),"")
A24: 1001 | B24: =_xlfn.IFNA(INDEX('Attandance Tracker'!$B$3:$B$30,MATCH($A23,'Attandance Tracker'!$A$3:$A$30,0)),"") -> Amit | C24: =_xlfn.IFNA(INDEX('Attandance Tracker'!$C$3:$C$30,MATCH($A24,'Attandance Tracker'!$A$3:$A$30,0)),"") -> Management | D24: 21 | E24: 0.33333333 | F24: 0.75 | G24: =IF(I24="Present",MIN(F24-E24,8/24),IF(I24="Absent",8/24,0)) -> 0.33333333 | H24: =IF(I24="Present",MAX(0,F24-E24-8/24),0) -> 0.083333333 | I24: =IFERROR(IF(INDEX('Attandance Tracker'!$D$3:$AH$50,MATCH($A24,'Attandance Tracker'!$A$3:$A$50,0),DAY($D24))="P","Present",IF(INDEX('Attandance Tracker'!$D$3:$AH$50,MATCH($A24,'Attandance Tracker'!$A$3:$A$50,0),DAY($D24))="A","Absent","Leave")),"") -> Present | K24: =IFERROR(INDEX($A$4:$A$1000,SMALL(IF($A$4:$A$1000=$O$2,ROW($A$4:$A$1000)-3),ROW(A21))),"") | L24: =IFERROR(INDEX($B$4:$B$1000,SMALL(IF($A$4:$A$1000=$O$2,ROW($A$4:$A$1000)-3),ROW(A21))),"") | M24: =IFERROR(INDEX($C$4:$C$1000,SMALL(IF($A$4:$A$1000=$O$2,ROW($A$4:$A$1000)-3),ROW(A21))),"") | N24: =IFERROR(INDEX($D$4:$D$1000,SMALL(IF($A$4:$A$1000=$O$2,ROW($A$4:$A$1000)-3),ROW(A21))),"") | O24: =IFERROR(INDEX($E$4:$E$1000,SMALL(IF($A$4:$A$1000=$O$2,ROW($A$4:$A$1000)-3),ROW(A21))),"") | P24: =IFERROR(INDEX($F$4:$F$1000,SMALL(IF($A$4:$A$1000=$O$2,ROW($A$4:$A$1000)-3),ROW(A21))),"") | Q24: =IFERROR(INDEX($G$4:$G$1000,SMALL(IF($A$4:$A$1000=$O$2,ROW($A$4:$A$1000)-3),ROW(A21))),"") | R24: =IFERROR(INDEX($H$4:$H$1000,SMALL(IF($A$4:$A$1000=$O$2,ROW($A$4:$A$1000)-3),ROW(A21))),"") | S24: =IFERROR(INDEX($I$4:$I$1000,SMALL(IF($A$4:$A$1000=$O$2,ROW($A$4:$A$1000)-3),ROW(A21))),"")
A25: 1001 | B25: =_xlfn.IFNA(INDEX('Attandance Tracker'!$B$3:$B$30,MATCH($A23,'Attandance Tracker'!$A$3:$A$30,0)),"") -> Amit | C25: =_xlfn.IFNA(INDEX('Attandance Tracker'!$C$3:$C$30,MATCH($A25,'Attandance Tracker'!$A$3:$A$30,0)),"") -> Management | D25: 22 | E25: 0.375 | F25: 0.75 | G25: =IF(I25="Present",MIN(F25-E25,8/24),IF(I25="Absent",8/24,0)) -> 0.33333333 | H25: =IF(I25="Present",MAX(0,F25-E25-8/24),0) -> 0.041666667 | I25: =IFERROR(IF(INDEX('Attandance Tracker'!$D$3:$AH$50,MATCH($A25,'Attandance Tracker'!$A$3:$A$50,0),DAY($D25))="P","Present",IF(INDEX('Attandance Tracker'!$D$3:$AH$50,MATCH($A25,'Attandance Tracker'!$A$3:$A$50,0),DAY($D25))="A","Absent","Leave")),"") -> Present | K25: =IFERROR(INDEX($A$4:$A$1000,SMALL(IF($A$4:$A$1000=$O$2,ROW($A$4:$A$1000)-3),ROW(A22))),"") | L25: =IFERROR(INDEX($B$4:$B$1000,SMALL(IF($A$4:$A$1000=$O$2,ROW($A$4:$A$1000)-3),ROW(A22))),"") | M25: =IFERROR(INDEX($C$4:$C$1000,SMALL(IF($A$4:$A$1000=$O$2,ROW($A$4:$A$1000)-3),ROW(A22))),"") | N25: =IFERROR(INDEX($D$4:$D$1000,SMALL(IF($A$4:$A$1000=$O$2,ROW($A$4:$A$1000)-3),ROW(A22))),"") | O25: =IFERROR(INDEX($E$4:$E$1000,SMALL(IF($A$4:$A$1000=$O$2,ROW($A$4:$A$1000)-3),ROW(A22))),"") | P25: =IFERROR(INDEX($F$4:$F$1000,SMALL(IF($A$4:$A$1000=$O$2,ROW($A$4:$A$1000)-3),ROW(A22))),"") | Q25: =IFERROR(INDEX($G$4:$G$1000,SMALL(IF($A$4:$A$1000=$O$2,ROW($A$4:$A$1000)-3),ROW(A22))),"") | R25: =IFERROR(INDEX($H$4:$H$1000,SMALL(IF($A$4:$A$1000=$O$2,ROW($A$4:$A$1000)-3),ROW(A22))),"") | S25: =IFERROR(INDEX($I$4:$I$1000,SMALL(IF($A$4:$A$1000=$O$2,ROW($A$4:$A$1000)-3),ROW(A22))),"")
A26: 1001 | B26: =_xlfn.IFNA(INDEX('Attandance Tracker'!$B$3:$B$30,MATCH($A24,'Attandance Tracker'!$A$3:$A$30,0)),"") -> Amit | C26: =_xlfn.IFNA(INDEX('Attandance Tracker'!$C$3:$C$30,MATCH($A26,'Attandance Tracker'!$A$3:$A$30,0)),"") -> Management | D26: 23 | E26: 0.375 | F26: 0.83333333 | G26: =IF(I26="Present",MIN(F26-E26,8/24),IF(I26="Absent",8/24,0)) -> 0.33333333 | H26: =IF(I26="Present",MAX(0,F26-E26-8/24),0) -> 0.125 | I26: =IFERROR(IF(INDEX('Attandance Tracker'!$D$3:$AH$50,MATCH($A26,'Attandance Tracker'!$A$3:$A$50,0),DAY($D26))="P","Present",IF(INDEX('Attandance Tracker'!$D$3:$AH$50,MATCH($A26,'Attandance Tracker'!$A$3:$A$50,0),DAY($D26))="A","Absent","Leave")),"") -> Present | K26: =IFERROR(INDEX($A$4:$A$1000,SMALL(IF($A$4:$A$1000=$O$2,ROW($A$4:$A$1000)-3),ROW(A23))),"") | L26: =IFERROR(INDEX($B$4:$B$1000,SMALL(IF($A$4:$A$1000=$O$2,ROW($A$4:$A$1000)-3),ROW(A23))),"") | M26: =IFERROR(INDEX($C$4:$C$1000,SMALL(IF($A$4:$A$1000=$O$2,ROW($A$4:$A$1000)-3),ROW(A23))),"") | N26: =IFERROR(INDEX($D$4:$D$1000,SMALL(IF($A$4:$A$1000=$O$2,ROW($A$4:$A$1000)-3),ROW(A23))),"") | O26: =IFERROR(INDEX($E$4:$E$1000,SMALL(IF($A$4:$A$1000=$O$2,ROW($A$4:$A$1000)-3),ROW(A23))),"") | P26: =IFERROR(INDEX($F$4:$F$1000,SMALL(IF($A$4:$A$1000=$O$2,ROW($A$4:$A$1000)-3),ROW(A23))),"") | Q26: =IFERROR(INDEX($G$4:$G$1000,SMALL(IF($A$4:$A$1000=$O$2,ROW($A$4:$A$1000)-3),ROW(A23))),"") | R26: =IFERROR(INDEX($H$4:$H$1000,SMALL(IF($A$4:$A$1000=$O$2,ROW($A$4:$A$1000)-3),ROW(A23))),"") | S26: =IFERROR(INDEX($I$4:$I$1000,SMALL(IF($A$4:$A$1000=$O$2,ROW($A$4:$A$1000)-3),ROW(A23))),"")
A27: 1001 | B27: =_xlfn.IFNA(INDEX('Attandance Tracker'!$B$3:$B$30,MATCH($A25,'Attandance Tracker'!$A$3:$A$30,0)),"") -> Amit | C27: =_xlfn.IFNA(INDEX('Attandance Tracker'!$C$3:$C$30,MATCH($A27,'Attandance Tracker'!$A$3:$A$30,0)),"") -> Management | D27: 24 | E27: 0.375 | F27: 0.83333333 | G27: =IF(I27="Present",MIN(F27-E27,8/24),IF(I27="Absent",8/24,0)) -> 0.33333333 | H27: =IF(I27="Present",MAX(0,F27-E27-8/24),0) -> 0 | I27: =IFERROR(IF(INDEX('Attandance Tracker'!$D$3:$AH$50,MATCH($A27,'Attandance Tracker'!$A$3:$A$50,0),DAY($D27))="P","Present",IF(INDEX('Attandance Tracker'!$D$3:$AH$50,MATCH($A27,'Attandance Tracker'!$A$3:$A$50,0),DAY($D27))="A","Absent","Leave")),"") -> Absent | K27: =IFERROR(INDEX($A$4:$A$1000,SMALL(IF($A$4:$A$1000=$O$2,ROW($A$4:$A$1000)-3),ROW(A24))),"") | L27: =IFERROR(INDEX($B$4:$B$1000,SMALL(IF($A$4:$A$1000=$O$2,ROW($A$4:$A$1000)-3),ROW(A24))),"") | M27: =IFERROR(INDEX($C$4:$C$1000,SMALL(IF($A$4:$A$1000=$O$2,ROW($A$4:$A$1000)-3),ROW(A24))),"") | N27: =IFERROR(INDEX($D$4:$D$1000,SMALL(IF($A$4:$A$1000=$O$2,ROW($A$4:$A$1000)-3),ROW(A24))),"") | O27: =IFERROR(INDEX($E$4:$E$1000,SMALL(IF($A$4:$A$1000=$O$2,ROW($A$4:$A$1000)-3),ROW(A24))),"") | P27: =IFERROR(INDEX($F$4:$F$1000,SMALL(IF($A$4:$A$1000=$O$2,ROW($A$4:$A$1000)-3),ROW(A24))),"") | Q27: =IFERROR(INDEX($G$4:$G$1000,SMALL(IF($A$4:$A$1000=$O$2,ROW($A$4:$A$1000)-3),ROW(A24))),"") | R27: =IFERROR(INDEX($H$4:$H$1000,SMALL(IF($A$4:$A$1000=$O$2,ROW($A$4:$A$1000)-3),ROW(A24))),"") | S27: =IFERROR(INDEX($I$4:$I$1000,SMALL(IF($A$4:$A$1000=$O$2,ROW($A$4:$A$1000)-3),ROW(A24))),"")
A28: 1001 | B28: =_xlfn.IFNA(INDEX('Attandance Tracker'!$B$3:$B$30,MATCH($A26,'Attandance Tracker'!$A$3:$A$30,0)),"") -> Amit | C28: =_xlfn.IFNA(INDEX('Attandance Tracker'!$C$3:$C$30,MATCH($A28,'Attandance Tracker'!$A$3:$A$30,0)),"") -> Management | D28: 25 | E28: 0.33333333 | F28: 0.83333333 | G28: =IF(I28="Present",MIN(F28-E28,8/24),IF(I28="Absent",8/24,0)) -> 0.33333333 | H28: =IF(I28="Present",MAX(0,F28-E28-8/24),0) -> 0 | I28: =IFERROR(IF(INDEX('Attandance Tracker'!$D$3:$AH$50,MATCH($A28,'Attandance Tracker'!$A$3:$A$50,0),DAY($D28))="P","Present",IF(INDEX('Attandance Tracker'!$D$3:$AH$50,MATCH($A28,'Attandance Tracker'!$A$3:$A$50,0),DAY($D28))="A","Absent","Leave")),"") -> Absent | K28: =IFERROR(INDEX($A$4:$A$1000,SMALL(IF($A$4:$A$1000=$O$2,ROW($A$4:$A$1000)-3),ROW(A25))),"") | L28: =IFERROR(INDEX($B$4:$B$1000,SMALL(IF($A$4:$A$1000=$O$2,ROW($A$4:$A$1000)-3),ROW(A25))),"") | M28: =IFERROR(INDEX($C$4:$C$1000,SMALL(IF($A$4:$A$1000=$O$2,ROW($A$4:$A$1000)-3),ROW(A25))),"") | N28: =IFERROR(INDEX($D$4:$D$1000,SMALL(IF($A$4:$A$1000=$O$2,ROW($A$4:$A$1000)-3),ROW(A25))),"") | O28: =IFERROR(INDEX($E$4:$E$1000,SMALL(IF($A$4:$A$1000=$O$2,ROW($A$4:$A$1000)-3),ROW(A25))),"") | P28: =IFERROR(INDEX($F$4:$F$1000,SMALL(IF($A$4:$A$1000=$O$2,ROW($A$4:$A$1000)-3),ROW(A25))),"") | Q28: =IFERROR(INDEX($G$4:$G$1000,SMALL(IF($A$4:$A$1000=$O$2,ROW($A$4:$A$1000)-3),ROW(A25))),"") | R28: =IFERROR(INDEX($H$4:$H$1000,SMALL(IF($A$4:$A$1000=$O$2,ROW($A$4:$A$1000)-3),ROW(A25))),"") | S28: =IFERROR(INDEX($I$4:$I$1000,SMALL(IF($A$4:$A$1000=$O$2,ROW($A$4:$A$1000)-3),ROW(A25))),"")
A29: 1001 | B29: =_xlfn.IFNA(INDEX('Attandance Tracker'!$B$3:$B$30,MATCH($A27,'Attandance Tracker'!$A$3:$A$30,0)),"") -> Amit | C29: =_xlfn.IFNA(INDEX('Attandance Tracker'!$C$3:$C$30,MATCH($A29,'Attandance Tracker'!$A$3:$A$30,0)),"") -> Management | D29: 26 | E29: 0.33333333 | F29: 0.79166667 | G29: =IF(I29="Present",MIN(F29-E29,8/24),IF(I29="Absent",8/24,0)) -> 0 | H29: =IF(I29="Present",MAX(0,F29-E29-8/24),0) -> 0 | I29: =IFERROR(IF(INDEX('Attandance Tracker'!$D$3:$AH$50,MATCH($A29,'Attandance Tracker'!$A$3:$A$50,0),DAY($D29))="P","Present",IF(INDEX('Attandance Tracker'!$D$3:$AH$50,MATCH($A29,'Attandance Tracker'!$A$3:$A$50,0),DAY($D29))="A","Absent","Leave")),"") -> Leave | K29: =IFERROR(INDEX($A$4:$A$1000,SMALL(IF($A$4:$A$1000=$O$2,ROW($A$4:$A$1000)-3),ROW(A26))),"") | L29: =IFERROR(INDEX($B$4:$B$1000,SMALL(IF($A$4:$A$1000=$O$2,ROW($A$4:$A$1000)-3),ROW(A26))),"") | M29: =IFERROR(INDEX($C$4:$C$1000,SMALL(IF($A$4:$A$1000=$O$2,ROW($A$4:$A$1000)-3),ROW(A26))),"") | N29: =IFERROR(INDEX($D$4:$D$1000,SMALL(IF($A$4:$A$1000=$O$2,ROW($A$4:$A$1000)-3),ROW(A26))),"") | O29: =IFERROR(INDEX($E$4:$E$1000,SMALL(IF($A$4:$A$1000=$O$2,ROW($A$4:$A$1000)-3),ROW(A26))),"") | P29: =IFERROR(INDEX($F$4:$F$1000,SMALL(IF($A$4:$A$1000=$O$2,ROW($A$4:$A$1000)-3),ROW(A26))),"") | Q29: =IFERROR(INDEX($G$4:$G$1000,SMALL(IF($A$4:$A$1000=$O$2,ROW($A$4:$A$1000)-3),ROW(A26))),"") | R29: =IFERROR(INDEX($H$4:$H$1000,SMALL(IF($A$4:$A$1000=$O$2,ROW($A$4:$A$1000)-3),ROW(A26))),"") | S29: =IFERROR(INDEX($I$4:$I$1000,SMALL(IF($A$4:$A$1000=$O$2,ROW($A$4:$A$1000)-3),ROW(A26))),"")
A30: 1001 | B30: =_xlfn.IFNA(INDEX('Attandance Tracker'!$B$3:$B$30,MATCH($A28,'Attandance Tracker'!$A$3:$A$30,0)),"") -> Amit | C30: =_xlfn.IFNA(INDEX('Attandance Tracker'!$C$3:$C$30,MATCH($A30,'Attandance Tracker'!$A$3:$A$30,0)),"") -> Management | D30: 27 | E30: 0.33333333 | F30: 0.75 | G30: =IF(I30="Present",MIN(F30-E30,8/24),IF(I30="Absent",8/24,0)) -> 0.33333333 | H30: =IF(I30="Present",MAX(0,F30-E30-8/24),0) -> 0.083333333 | I30: =IFERROR(IF(INDEX('Attandance Tracker'!$D$3:$AH$50,MATCH($A30,'Attandance Tracker'!$A$3:$A$50,0),DAY($D30))="P","Present",IF(INDEX('Attandance Tracker'!$D$3:$AH$50,MATCH($A30,'Attandance Tracker'!$A$3:$A$50,0),DAY($D30))="A","Absent","Leave")),"") -> Present
A31: 1001 | B31: =_xlfn.IFNA(INDEX('Attandance Tracker'!$B$3:$B$30,MATCH($A29,'Attandance Tracker'!$A$3:$A$30,0)),"") -> Amit | C31: =_xlfn.IFNA(INDEX('Attandance Tracker'!$C$3:$C$30,MATCH($A31,'Attandance Tracker'!$A$3:$A$30,0)),"") -> Management | D31: 28 | E31: 0.33333333 | F31: 0.75 | G31: =IF(I31="Present",MIN(F31-E31,8/24),IF(I31="Absent",8/24,0)) -> 0.33333333 | H31: =IF(I31="Present",MAX(0,F31-E31-8/24),0) -> 0.083333333 | I31: =IFERROR(IF(INDEX('Attandance Tracker'!$D$3:$AH$50,MATCH($A31,'Attandance Tracker'!$A$3:$A$50,0),DAY($D31))="P","Present",IF(INDEX('Attandance Tracker'!$D$3:$AH$50,MATCH($A31,'Attandance Tracker'!$A$3:$A$50,0),DAY($D31))="A","Absent","Leave")),"") -> Present
A32: 1001 | B32: =_xlfn.IFNA(INDEX('Attandance Tracker'!$B$3:$B$30,MATCH($A30,'Attandance Tracker'!$A$3:$A$30,0)),"") -> Amit | C32: =_xlfn.IFNA(INDEX('Attandance Tracker'!$C$3:$C$30,MATCH($A32,'Attandance Tracker'!$A$3:$A$30,0)),"") -> Management | D32: 29 | E32: 0.33333333 | F32: 0.75 | G32: =IF(I32="Present",MIN(F32-E32,8/24),IF(I32="Absent",8/24,0)) -> 0.33333333 | H32: =IF(I32="Present",MAX(0,F32-E32-8/24),0) -> 0.083333333 | I32: =IFERROR(IF(INDEX('Attandance Tracker'!$D$3:$AH$50,MATCH($A32,'Attandance Tracker'!$A$3:$A$50,0),DAY($D32))="P","Present",IF(INDEX('Attandance Tracker'!$D$3:$AH$50,MATCH($A32,'Attandance Tracker'!$A$3:$A$50,0),DAY($D32))="A","Absent","Leave")),"") -> Present
A33: 1001 | B33: =_xlfn.IFNA(INDEX('Attandance Tracker'!$B$3:$B$30,MATCH($A31,'Attandance Tracker'!$A$3:$A$30,0)),"") -> Amit | C33: =_xlfn.IFNA(INDEX('Attandance Tracker'!$C$3:$C$30,MATCH($A33,'Attandance Tracker'!$A$3:$A$30,0)),"") -> Management | D33: 30 | E33: 0.33333333 | F33: 0.75 | G33: =IF(I33="Present",MIN(F33-E33,8/24),IF(I33="Absent",8/24,0)) -> 0 | H33: =IF(I33="Present",MAX(0,F33-E33-8/24),0) -> 0 | I33: =IFERROR(IF(INDEX('Attandance Tracker'!$D$3:$AH$50,MATCH($A33,'Attandance Tracker'!$A$3:$A$50,0),DAY($D33))="P","Present",IF(INDEX('Attandance Tracker'!$D$3:$AH$50,MATCH($A33,'Attandance Tracker'!$A$3:$A$50,0),DAY($D33))="A","Absent","Leave")),"") -> Leave
A34: 1001 | B34: =_xlfn.IFNA(INDEX('Attandance Tracker'!$B$3:$B$30,MATCH($A34,'Attandance Tracker'!$A$3:$A$30,0)),"") -> Amit | C34: =_xlfn.IFNA(INDEX('Attandance Tracker'!$C$3:$C$30,MATCH($A34,'Attandance Tracker'!$A$3:$A$30,0)),"") -> Management | D34: 31 | E34: 0 | F34: 0 | G34: =IF(I34="Present",MIN(F34-E34,8/24),IF(I34="Absent",8/24,0)) -> 0 | H34: =IF(I34="Present",MAX(0,F34-E34-8/24),0) -> 0 | I34: =IFERROR(IF(INDEX('Attandance Tracker'!$D$3:$AH$50,MATCH($A34,'Attandance Tracker'!$A$3:$A$50,0),DAY($D34))="P","Present",IF(INDEX('Attandance Tracker'!$D$3:$AH$50,MATCH($A34,'Attandance Tracker'!$A$3:$A$50,0),DAY($D34))="A","Absent","Leave")),"") -> Leave
A35: 1002 | B35: =_xlfn.IFNA(INDEX('Attandance Tracker'!$B$3:$B$30,MATCH($A35,'Attandance Tracker'!$A$3:$A$30,0)),"") -> Ravi | C35: =_xlfn.IFNA(INDEX('Attandance Tracker'!$C$3:$C$30,MATCH($A35,'Attandance Tracker'!$A$3:$A$30,0)),"") -> Management | D35: 1 | E35: 0.33333333 | F35: 0.75 | G35: =IF(I35="Present",MIN(F35-E35,8/24),IF(I35="Absent",8/24,0)) -> 0.33333333 | H35: =IF(I35="Present",MAX(0,F35-E35-8/24),0) -> 0.083333333 | I35: =IFERROR(IF(INDEX('Attandance Tracker'!$D$3:$AH$50,MATCH($A35,'Attandance Tracker'!$A$3:$A$50,0),DAY($D35))="P","Present",IF(INDEX('Attandance Tracker'!$D$3:$AH$50,MATCH($A35,'Attandance Tracker'!$A$3:$A$50,0),DAY($D35))="A","Absent","Leave")),"") -> Present
A36: 1002 | B36: =_xlfn.IFNA(INDEX('Attandance Tracker'!$B$3:$B$30,MATCH($A36,'Attandance Tracker'!$A$3:$A$30,0)),"") -> Ravi | C36: =_xlfn.IFNA(INDEX('Attandance Tracker'!$C$3:$C$30,MATCH($A36,'Attandance Tracker'!$A$3:$A$30,0)),"") -> Management | D36: 2 | E36: 0.375 | F36: 0.75 | G36: =IF(I36="Present",MIN(F36-E36,8/24),IF(I36="Absent",8/24,0)) -> 0.33333333 | H36: =IF(I36="Present",MAX(0,F36-E36-8/24),0) -> 0.041666667 | I36: =IFERROR(IF(INDEX('Attandance Tracker'!$D$3:$AH$50,MATCH($A36,'Attandance Tracker'!$A$3:$A$50,0),DAY($D36))="P","Present",IF(INDEX('Attandance Tracker'!$D$3:$AH$50,MATCH($A36,'Attandance Tracker'!$A$3:$A$50,0),DAY($D36))="A","Absent","Leave")),"") -> Present
A37: 1002 | B37: =_xlfn.IFNA(INDEX('Attandance Tracker'!$B$3:$B$30,MATCH($A37,'Attandance Tracker'!$A$3:$A$30,0)),"") -> Ravi | C37: =_xlfn.IFNA(INDEX('Attandance Tracker'!$C$3:$C$30,MATCH($A37,'Attandance Tracker'!$A$3:$A$30,0)),"") -> Management | D37: 3 | E37: 0.375 | F37: 0.83333333 | G37: =IF(I37="Present",MIN(F37-E37,8/24),IF(I37="Absent",8/24,0)) -> 0.33333333 | H37: =IF(I37="Present",MAX(0,F37-E37-8/24),0) -> 0.125 | I37: =IFERROR(IF(INDEX('Attandance Tracker'!$D$3:$AH$50,MATCH($A37,'Attandance Tracker'!$A$3:$A$50,0),DAY($D37))="P","Present",IF(INDEX('Attandance Tracker'!$D$3:$AH$50,MATCH($A37,'Attandance Tracker'!$A$3:$A$50,0),DAY($D37))="A","Absent","Leave")),"") -> Present
A38: 1002 | B38: =_xlfn.IFNA(INDEX('Attandance Tracker'!$B$3:$B$30,MATCH($A38,'Attandance Tracker'!$A$3:$A$30,0)),"") -> Ravi | C38: =_xlfn.IFNA(INDEX('Attandance Tracker'!$C$3:$C$30,MATCH($A38,'Attandance Tracker'!$A$3:$A$30,0)),"") -> Management | D38: 4 | E38: 0.375 | F38: 0.83333333 | G38: =IF(I38="Present",MIN(F38-E38,8/24),IF(I38="Absent",8/24,0)) -> 0 | H38: =IF(I38="Present",MAX(0,F38-E38-8/24),0) -> 0 | I38: =IFERROR(IF(INDEX('Attandance Tracker'!$D$3:$AH$50,MATCH($A38,'Attandance Tracker'!$A$3:$A$50,0),DAY($D38))="P","Present",IF(INDEX('Attandance Tracker'!$D$3:$AH$50,MATCH($A38,'Attandance Tracker'!$A$3:$A$50,0),DAY($D38))="A","Absent","Leave")),"") -> Leave
A39: 1002 | B39: =_xlfn.IFNA(INDEX('Attandance Tracker'!$B$3:$B$30,MATCH($A39,'Attandance Tracker'!$A$3:$A$30,0)),"") -> Ravi | C39: =_xlfn.IFNA(INDEX('Attandance Tracker'!$C$3:$C$30,MATCH($A39,'Attandance Tracker'!$A$3:$A$30,0)),"") -> Management | D39: 5 | E39: 0.33333333 | F39: 0.83333333 | G39: =IF(I39="Present",MIN(F39-E39,8/24),IF(I39="Absent",8/24,0)) -> 0 | H39: =IF(I39="Present",MAX(0,F39-E39-8/24),0) -> 0 | I39: =IFERROR(IF(INDEX('Attandance Tracker'!$D$3:$AH$50,MATCH($A39,'Attandance Tracker'!$A$3:$A$50,0),DAY($D39))="P","Present",IF(INDEX('Attandance Tracker'!$D$3:$AH$50,MATCH($A39,'Attandance Tracker'!$A$3:$A$50,0),DAY($D39))="A","Absent","Leave")),"") -> Leave
A40: 1002 | B40: =_xlfn.IFNA(INDEX('Attandance Tracker'!$B$3:$B$30,MATCH($A40,'Attandance Tracker'!$A$3:$A$30,0)),"") -> Ravi | C40: =_xlfn.IFNA(INDEX('Attandance Tracker'!$C$3:$C$30,MATCH($A40,'Attandance Tracker'!$A$3:$A$30,0)),"") -> Management | D40: 6 | E40: 0.33333333 | F40: 0.79166667 | G40: =IF(I40="Present",MIN(F40-E40,8/24),IF(I40="Absent",8/24,0)) -> 0.33333333 | H40: =IF(I40="Present",MAX(0,F40-E40-8/24),0) -> 0.125 | I40: =IFERROR(IF(INDEX('Attandance Tracker'!$D$3:$AH$50,MATCH($A40,'Attandance Tracker'!$A$3:$A$50,0),DAY($D40))="P","Present",IF(INDEX('Attandance Tracker'!$D$3:$AH$50,MATCH($A40,'Attandance Tracker'!$A$3:$A$50,0),DAY($D40))="A","Absent","Leave")),"") -> Present
A41: 1002 | B41: =_xlfn.IFNA(INDEX('Attandance Tracker'!$B$3:$B$30,MATCH($A41,'Attandance Tracker'!$A$3:$A$30,0)),"") -> Ravi | C41: =_xlfn.IFNA(INDEX('Attandance Tracker'!$C$3:$C$30,MATCH($A41,'Attandance Tracker'!$A$3:$A$30,0)),"") -> Management | D41: 7 | E41: 0.33333333 | F41: 0.75 | G41: =IF(I41="Present",MIN(F41-E41,8/24),IF(I41="Absent",8/24,0)) -> 0.33333333 | H41: =IF(I41="Present",MAX(0,F41-E41-8/24),0) -> 0.083333333 | I41: =IFERROR(IF(INDEX('Attandance Tracker'!$D$3:$AH$50,MATCH($A41,'Attandance Tracker'!$A$3:$A$50,0),DAY($D41))="P","Present",IF(INDEX('Attandance Tracker'!$D$3:$AH$50,MATCH($A41,'Attandance Tracker'!$A$3:$A$50,0),DAY($D41))="A","Absent","Leave")),"") -> Present
A42: 1002 | B42: =_xlfn.IFNA(INDEX('Attandance Tracker'!$B$3:$B$30,MATCH($A42,'Attandance Tracker'!$A$3:$A$30,0)),"") -> Ravi | C42: =_xlfn.IFNA(INDEX('Attandance Tracker'!$C$3:$C$30,MATCH($A42,'Attandance Tracker'!$A$3:$A$30,0)),"") -> Management | D42: 8 | E42: 0.33333333 | F42: 0.75 | G42: =IF(I42="Present",MIN(F42-E42,8/24),IF(I42="Absent",8/24,0)) -> 0.33333333 | H42: =IF(I42="Present",MAX(0,F42-E42-8/24),0) -> 0.083333333 | I42: =IFERROR(IF(INDEX('Attandance Tracker'!$D$3:$AH$50,MATCH($A42,'Attandance Tracker'!$A$3:$A$50,0),DAY($D42))="P","Present",IF(INDEX('Attandance Tracker'!$D$3:$AH$50,MATCH($A42,'Attandance Tracker'!$A$3:$A$50,0),DAY($D42))="A","Absent","Leave")),"") -> Present
A43: 1002 | B43: =_xlfn.IFNA(INDEX('Attandance Tracker'!$B$3:$B$30,MATCH($A43,'Attandance Tracker'!$A$3:$A$30,0)),"") -> Ravi | C43: =_xlfn.IFNA(INDEX('Attandance Tracker'!$C$3:$C$30,MATCH($A43,'Attandance Tracker'!$A$3:$A$30,0)),"") -> Management | D43: 9 | E43: 0.33333333 | F43: 0.75 | G43: =IF(I43="Present",MIN(F43-E43,8/24),IF(I43="Absent",8/24,0)) -> 0.33333333 | H43: =IF(I43="Present",MAX(0,F43-E43-8/24),0) -> 0 | I43: =IFERROR(IF(INDEX('Attandance Tracker'!$D$3:$AH$50,MATCH($A43,'Attandance Tracker'!$A$3:$A$50,0),DAY($D43))="P","Present",IF(INDEX('Attandance Tracker'!$D$3:$AH$50,MATCH($A43,'Attandance Tracker'!$A$3:$A$50,0),DAY($D43))="A","Absent","Leave")),"") -> Absent
A44: 1002 | B44: =_xlfn.IFNA(INDEX('Attandance Tracker'!$B$3:$B$30,MATCH($A44,'Attandance Tracker'!$A$3:$A$30,0)),"") -> Ravi | C44: =_xlfn.IFNA(INDEX('Attandance Tracker'!$C$3:$C$30,MATCH($A44,'Attandance Tracker'!$A$3:$A$30,0)),"") -> Management | D44: 10 | E44: 0.33333333 | F44: 0.75 | G44: =IF(I44="Present",MIN(F44-E44,8/24),IF(I44="Absent",8/24,0)) -> 0.33333333 | H44: =IF(I44="Present",MAX(0,F44-E44-8/24),0) -> 0.083333333 | I44: =IFERROR(IF(INDEX('Attandance Tracker'!$D$3:$AH$50,MATCH($A44,'Attandance Tracker'!$A$3:$A$50,0),DAY($D44))="P","Present",IF(INDEX('Attandance Tracker'!$D$3:$AH$50,MATCH($A44,'Attandance Tracker'!$A$3:$A$50,0),DAY($D44))="A","Absent","Leave")),"") -> Present
A45: 1002 | B45: =_xlfn.IFNA(INDEX('Attandance Tracker'!$B$3:$B$30,MATCH($A45,'Attandance Tracker'!$A$3:$A$30,0)),"") -> Ravi | C45: =_xlfn.IFNA(INDEX('Attandance Tracker'!$C$3:$C$30,MATCH($A45,'Attandance Tracker'!$A$3:$A$30,0)),"") -> Management | D45: 11 | E45: 0.33333333 | F45: 0.83333333 | G45: =IF(I45="Present",MIN(F45-E45,8/24),IF(I45="Absent",8/24,0)) -> 0.33333333 | H45: =IF(I45="Present",MAX(0,F45-E45-8/24),0) -> 0.16666667 | I45: =IFERROR(IF(INDEX('Attandance Tracker'!$D$3:$AH$50,MATCH($A45,'Attandance Tracker'!$A$3:$A$50,0),DAY($D45))="P","Present",IF(INDEX('Attandance Tracker'!$D$3:$AH$50,MATCH($A45,'Attandance Tracker'!$A$3:$A$50,0),DAY($D45))="A","Absent","Leave")),"") -> Present
...

Sheet Monthly Summary
A3: Emp ID | B3: Employee Name | C3: Department | D3: Present Days | E3: Leave Days | F3: Absent Days | G3: Base Present Hrs (≤8/day) | H3: Overtime Hrs (>8/day) | I3: Base salary | J3: OT salary | K3: Total Salary
A4: 1001 | B4: Amit | C4: Management | D4: =COUNTIFS('Daily Entry'!A:A, A4, 'Daily Entry'!I:I, "Present") -> 24 | E4: =COUNTIFS('Daily Entry'!A:A, A4, 'Daily Entry'!I:I, "Leave") -> 4 | F4: =COUNTIFS('Daily Entry'!A:A, A4, 'Daily Entry'!I:I, "Absent") -> 3 | G4: =IFERROR(SUMIF('Daily Entry'!A:A,A4,'Daily Entry'!G:G),0) -> 9 | H4: =IFERROR(SUMIF('Daily Entry'!A:A, A4, 'Daily Entry'!H:H), 0) -> 2.3333333 | I4: =(G4/TIME(1,0,0))*VLOOKUP(C4,'Pay Rate'!A:B,2,0) -> 75600 | J4: =(H4/TIME(1,0,0))*VLOOKUP(C4,'Pay Rate'!A:C,3,0) -> 39200 | K4: =I4+J4 -> 114800
A5: 1002 | B5: Ravi | C5: Management | D5: =COUNTIFS('Daily Entry'!A:A, A5, 'Daily Entry'!I:I, "Present") -> 28 | E5: =COUNTIFS('Daily Entry'!A:A, A5, 'Daily Entry'!I:I, "Leave") -> 2 | F5: =COUNTIFS('Daily Entry'!A:A, A5, 'Daily Entry'!I:I, "Absent") -> 1 | G5: =IFERROR(SUMIF('Daily Entry'!A:A,A5,'Daily Entry'!G:G),0) -> 9.6666667 | H5: =IFERROR(SUMIF('Daily Entry'!A:A, A5, 'Daily Entry'!H:H), 0) -> 3.1666667 | I5: =(G5/TIME(1,0,0))*VLOOKUP(C5,'Pay Rate'!A:B,2,0) -> 81200 | J5: =(H5/TIME(1,0,0))*VLOOKUP(C5,'Pay Rate'!A:C,3,0) -> 53200 | K5: =I5+J5 -> 134400
A6: 1003 | B6: Neha | C6: HR | D6: =COUNTIFS('Daily Entry'!A:A, A6, 'Daily Entry'!I:I, "Present") -> 31 | E6: =COUNTIFS('Daily Entry'!A:A, A6, 'Daily Entry'!I:I, "Leave") -> 0 | F6: =COUNTIFS('Daily Entry'!A:A, A6, 'Daily Entry'!I:I, "Absent") -> 0 | G6: =IFERROR(SUMIF('Daily Entry'!A:A,A6,'Daily Entry'!G:G),0) -> 10.333333 | H6: =IFERROR(SUMIF('Daily Entry'!A:A, A6, 'Daily Entry'!H:H), 0) -> 4.2083333 | I6: =(G6/TIME(1,0,0))*VLOOKUP(C6,'Pay Rate'!A:B,2,0) -> 74400 | J6: =(H6/TIME(1,0,0))*VLOOKUP(C6,'Pay Rate'!A:C,3,0) -> 60600 | K6: =I6+J6 -> 135000
A7: 1004 | B7: Priya | C7: Finance | D7: =COUNTIFS('Daily Entry'!A:A, A7, 'Daily Entry'!I:I, "Present") -> 29 | E7: =COUNTIFS('Daily Entry'!A:A, A7, 'Daily Entry'!I:I, "Leave") -> 0 | F7: =COUNTIFS('Daily Entry'!A:A, A7, 'Daily Entry'!I:I, "Absent") -> 2 | G7: =IFERROR(SUMIF('Daily Entry'!A:A,A7,'Daily Entry'!G:G),0) -> 10.333333 | H7: =IFERROR(SUMIF('Daily Entry'!A:A, A7, 'Daily Entry'!H:H), 0) -> 3.6666667 | I7: =(G7/TIME(1,0,0))*VLOOKUP(C7,'Pay Rate'!A:B,2,0) -> 99200 | J7: =(H7/TIME(1,0,0))*VLOOKUP(C7,'Pay Rate'!A:C,3,0) -> 70400 | K7: =I7+J7 -> 169600
A8: 1005 | B8: Rohit | C8: IT | D8: =COUNTIFS('Daily Entry'!A:A, A8, 'Daily Entry'!I:I, "Present") -> 30 | E8: =COUNTIFS('Daily Entry'!A:A, A8, 'Daily Entry'!I:I, "Leave") -> 1 | F8: =COUNTIFS('Daily Entry'!A:A, A8, 'Daily Entry'!I:I, "Absent") -> 0 | G8: =IFERROR(SUMIF('Daily Entry'!A:A,A8,'Daily Entry'!G:G),0) -> 10 | H8: =IFERROR(SUMIF('Daily Entry'!A:A, A8, 'Daily Entry'!H:H), 0) -> 3.875 | I8: =(G8/TIME(1,0,0))*VLOOKUP(C8,'Pay Rate'!A:B,2,0) -> 88800 | J8: =(H8/TIME(1,0,0))*VLOOKUP(C8,'Pay Rate'!A:C,3,0) -> 68820 | K8: =I8+J8 -> 157620
A9: 1006 | B9: Anjali | C9: Sales | D9: =COUNTIFS('Daily Entry'!A:A, A9, 'Daily Entry'!I:I, "Present") -> 31 | E9: =COUNTIFS('Daily Entry'!A:A, A9, 'Daily Entry'!I:I, "Leave") -> 0 | F9: =COUNTIFS('Daily Entry'!A:A, A9, 'Daily Entry'!I:I, "Absent") -> 0 | G9: =IFERROR(SUMIF('Daily Entry'!A:A,A9,'Daily Entry'!G:G),0) -> 10.333333 | H9: =IFERROR(SUMIF('Daily Entry'!A:A, A9, 'Daily Entry'!H:H), 0) -> 4.3333333 | I9: =(G9/TIME(1,0,0))*VLOOKUP(C9,'Pay Rate'!A:B,2,0) -> 66960 | J9: =(H9/TIME(1,0,0))*VLOOKUP(C9,'Pay Rate'!A:C,3,0) -> 56160 | K9: =I9+J9 -> 123120
A10: 1007 | B10: Vikas | C10: Operations | D10: =COUNTIFS('Daily Entry'!A:A, A10, 'Daily Entry'!I:I, "Present") -> 27 | E10: =COUNTIFS('Daily Entry'!A:A, A10, 'Daily Entry'!I:I, "Leave") -> 4 | F10: =COUNTIFS('Daily Entry'!A:A, A10, 'Daily Entry'!I:I, "Absent") -> 0 | G10: =IFERROR(SUMIF('Daily Entry'!A:A,A10,'Daily Entry'!G:G),0) -> 9 | H10: =IFERROR(SUMIF('Daily Entry'!A:A, A10, 'Daily Entry'!H:H), 0) -> 3.2916667 | I10: =(G10/TIME(1,0,0))*VLOOKUP(C10,'Pay Rate'!A:B,2,0) -> 69120 | J10: =(H10/TIME(1,0,0))*VLOOKUP(C10,'Pay Rate'!A:C,3,0) -> 50560 | K10: =I10+J10 -> 119680
A11: 1008 | B11: Pooja | C11: HR | D11: =COUNTIFS('Daily Entry'!A:A, A11, 'Daily Entry'!I:I, "Present") -> 31 | E11: =COUNTIFS('Daily Entry'!A:A, A11, 'Daily Entry'!I:I, "Leave") -> 0 | F11: =COUNTIFS('Daily Entry'!A:A, A11, 'Daily Entry'!I:I, "Absent") -> 0 | G11: =IFERROR(SUMIF('Daily Entry'!A:A,A11,'Daily Entry'!G:G),0) -> 10.333333 | H11: =IFERROR(SUMIF('Daily Entry'!A:A, A11, 'Daily Entry'!H:H), 0) -> 4.0416667 | I11: =(G11/TIME(1,0,0))*VLOOKUP(C11,'Pay Rate'!A:B,2,0) -> 74400 | J11: =(H11/TIME(1,0,0))*VLOOKUP(C11,'Pay Rate'!A:C,3,0) -> 58200 | K11: =I11+J11 -> 132600
A12: 1009 | B12: Arjun | C12: HR | D12: =COUNTIFS('Daily Entry'!A:A, A12, 'Daily Entry'!I:I, "Present") -> 24 | E12: =COUNTIFS('Daily Entry'!A:A, A12, 'Daily Entry'!I:I, "Leave") -> 4 | F12: =COUNTIFS('Daily Entry'!A:A, A12, 'Daily Entry'!I:I, "Absent") -> 3 | G12: =IFERROR(SUMIF('Daily Entry'!A:A,A12,'Daily Entry'!G:G),0) -> 9 | H12: =IFERROR(SUMIF('Daily Entry'!A:A, A12, 'Daily Entry'!H:H), 0) -> 3 | I12: =(G12/TIME(1,0,0))*VLOOKUP(C12,'Pay Rate'!A:B,2,0) -> 64800 | J12: =(H12/TIME(1,0,0))*VLOOKUP(C12,'Pay Rate'!A:C,3,0) -> 43200 | K12: =I12+J12 -> 108000
A13: 1010 | B13: Sneha | C13: Finance | D13: =COUNTIFS('Daily Entry'!A:A, A13, 'Daily Entry'!I:I, "Present") -> 28 | E13: =COUNTIFS('Daily Entry'!A:A, A13, 'Daily Entry'!I:I, "Leave") -> 2 | F13: =COUNTIFS('Daily Entry'!A:A, A13, 'Daily Entry'!I:I, "Absent") -> 1 | G13: =IFERROR(SUMIF('Daily Entry'!A:A,A13,'Daily Entry'!G:G),0) -> 9.6666667 | H13: =IFERROR(SUMIF('Daily Entry'!A:A, A13, 'Daily Entry'!H:H), 0) -> 3.5833333 | I13: =(G13/TIME(1,0,0))*VLOOKUP(C13,'Pay Rate'!A:B,2,0) -> 92800 | J13: =(H13/TIME(1,0,0))*VLOOKUP(C13,'Pay Rate'!A:C,3,0) -> 68800 | K13: =I13+J13 -> 161600
A14: 1011 | B14: Karan | C14: Finance | D14: =COUNTIFS('Daily Entry'!A:A, A14, 'Daily Entry'!I:I, "Present") -> 31 | E14: =COUNTIFS('Daily Entry'!A:A, A14, 'Daily Entry'!I:I, "Leave") -> 0 | F14: =COUNTIFS('Daily Entry'!A:A, A14, 'Daily Entry'!I:I, "Absent") -> 0 | G14: =IFERROR(SUMIF('Daily Entry'!A:A,A14,'Daily Entry'!G:G),0) -> 10.333333 | H14: =IFERROR(SUMIF('Daily Entry'!A:A, A14, 'Daily Entry'!H:H), 0) -> 3.875 | I14: =(G14/TIME(1,0,0))*VLOOKUP(C14,'Pay Rate'!A:B,2,0) -> 99200 | J14: =(H14/TIME(1,0,0))*VLOOKUP(C14,'Pay Rate'!A:C,3,0) -> 74400 | K14: =I14+J14 -> 173600
A15: 1012 | B15: Simran | C15: IT | D15: =COUNTIFS('Daily Entry'!A:A, A15, 'Daily Entry'!I:I, "Present") -> 29 | E15: =COUNTIFS('Daily Entry'!A:A, A15, 'Daily Entry'!I:I, "Leave") -> 0 | F15: =COUNTIFS('Daily Entry'!A:A, A15, 'Daily Entry'!I:I, "Absent") -> 2 | G15: =IFERROR(SUMIF('Daily Entry'!A:A,A15,'Daily Entry'!G:G),0) -> 10.333333 | H15: =IFERROR(SUMIF('Daily Entry'!A:A, A15, 'Daily Entry'!H:H), 0) -> 3.7083333 | I15: =(G15/TIME(1,0,0))*VLOOKUP(C15,'Pay Rate'!A:B,2,0) -> 91760 | J15: =(H15/TIME(1,0,0))*VLOOKUP(C15,'Pay Rate'!A:C,3,0) -> 65860 | K15: =I15+J15 -> 157620
... A31: 1028 | B31: Preeti | C31: IT | D31: =COUNTIFS('Daily Entry'!A:A, A31, 'Daily Entry'!I:I, "Present") -> 29 | E31: =COUNTIFS('Daily Entry'!A:A, A31, 'Daily Entry'!I:I, "Leave") -> 0 | F31: =COUNTIFS('Daily Entry'!A:A, A31, 'Daily Entry'!I:I, "Absent") -> 2 | G31: =IFERROR(SUMIF('Daily Entry'!A:A,A31,'Daily Entry'!G:G),0) -> 10.333333 | H31: =IFERROR(SUMIF('Daily Entry'!A:A, A31, 'Daily Entry'!H:H), 0) -> 3.625 | I31: =(G31/TIME(1,0,0))*VLOOKUP(C31,'Pay Rate'!A:B,2,0) -> 91760 | J31: =(H31/TIME(1,0,0))*VLOOKUP(C31,'Pay Rate'!A:C,3,0) -> 64380 | K31: =I31+J31 -> 156140

Sheet EmpList
A1: EmpID | B1: Name | C1: Dept
A2: 1001 | B2: aman | C2: labour
A3: 1002 | B3: anas | C3: supervisor
A4: 1003 | B4: axam | C4: labor
A5: 1004 | B5: ahil | C5: labor
A6: 1005 | B6: nikhil | C6: labor
A7: 1006 | B7: vikas | C7: manager
A8: 1007 | B8: khan | C8: worker
A9: 1008 | B9: raja | C9: tecaher
A10: 1009 | B10: suresh | C10: it
A11: 1010 | B11: akash | C11: hr
A12: 1011 | B12: kanha | C12: doctot
... A14: 1013 | B14: gai | C14: judge
A15: 1014 | B15: kala
A16: 1015 | B16: kaka
A17: 1016 | B17: manish
A18: 1017 | B18: naresh
A19: 1018 | B19: subash
A20: 1019 | B20: salaman
A21: 1020 | B21: suhail
A22: 1021 | B22: taimur alex
A23: 1022 | B23: alexa
A24: 1023
A25: 1024
A26: 1025
A27: 1026
A28: 1027
A29: 1028
A30: 1029
A31: 1030
A32: 1031
A33: 1032
A34: 1033
A35: 1034
... A48: 1047
